Workbook

Sheet 0
B2: FAM UPGRADE - WAVE 4
B4: 1 | C4: 2 | E4: 1 | F4: =E4+1 -> 2 | G4: =F4+1 -> 3 | H4: =G4+1 -> 4 | I4: =H4+1 -> 5 | J4: =I4+1 -> 6 | L4: =J4+1 -> 7 | N4: 1 | O4: 2
B5: FAM Wave 4 | C5: 1 | E5: =B5 -> FAM Wave 4 | L5: Conso. | N5: Common
C6: 2 | E6: - | H6: Detail | L6: - | N6: -
C7: 3 | E7: Item | F7: - | G7: - | H7: - | I7: Priority | J7: Note | L7: - | N7: -
C8: =ROW()-7 -> 1 | E8: =B5 -> FAM Wave 4 | F8: Enhancement | G8: Tài sản | H8: Dashboard tài sản hiển thị theo hướng visualize; có thể customize theo nhiều tiêu chí | I8: 1 | J8: Login vào là nhìn thấy luôn. Cần liệt kê rõ ràng role | L8: 1
C9: =ROW()-7 -> 2 | H9: Ẩn hiện tùy chọn tài sản vô hiệu hóa khỏi danh sách tài sản | I9: 2
C10: =ROW()-7 -> 3 | H10: Đổi vị trí hiển thị một số cột trong danh sách tài sản | I10: 2
C11: =ROW()-7 -> 4 | G11: Cấp tài sản | H11: Upload phiếu cấp tài sản theo danh sách | I11: 3
C12: =ROW()-7 -> 5 | G12: Auto xác nhận phiếu cấp tài sản | H12: Sau 20 ngày kể từ khi request bàn giao tài sản được tạo, user không có phản hồi, Hệ thống tự động xác nhận. | I12: 2
C13: =ROW()-7 -> 6 | G13: Intergration | H13: Atuto đồng bộ OMS khi orgchart thay đổi | I13: 2
C14: =ROW()-7 -> 7 | H14: Đồng bộ tiêu đề PO từ EMS sang FAM | I14: 2
C15: =ROW()-7 -> 8 | H15: Tài sản từ EMS, cột "Thông tin thời gian đưa vào sử dụng, Thời gian bắt đầu bảo hành" = thời gian PO được phê duyệt . | I15: 2
C16: =ROW()-7 -> 9 | G16: Thanh lý | H16: Bổ sung luồng phê duyệt cho ATM | I16: 3 | J16: Thêm thông tin as is và to be
C17: =ROW()-7 -> 10 | F17: New launch | G17: Modul kho | H17: Xuất - nhập kho tài sản Tiếp nhận yêu cầu xuất - nhập kho từ yêu cầu cấp ts, thanh lý tài sản, điều chuyển ts về kho. | I17: 1 | L17: 5
C18: =ROW()-7 -> 11 | G18: Modul sửa chữa tài sản | H18: Tạo yêu cầu sửa chữa tài sản thực hiện trên FAM => Hệ thống tạo yêu cầu (gửi link) sang Hệ thống ITSM và Cổng hỗ trợ chi nhánh trên intranet. Hoàn tất, yêu cầu đc feed back qua FAM | I18: 4 | J18: Cần Clear qui trình | L18: 3
C19: All
B22: Common | C22: -

Sheet 1
B2: DASHBOARD TÀI SẢN
B4: 1 | C4: 2 | D4: 3
B5: Mục tiêu | C5: Giao diện tổng quan, trực quan hóa dữ liệu
C6: Hỗ trợ đưa ra quyết định nhanh chóng
B8: Phạm vi | C8: Data tài sản theo phòng, ban orgchart
C9: Data tài sản theo trạng thái tài sản
C10: Biến động tài sản theo thời gian
C11: Tỷ lệ sử dụng tài sản
C12: Tài sản hết bảo hành, tài sản có thời gian sử dụng> 3 năm, > 5 năm
B13: Nghiệp vụ
C14: Dashboard tổng quan | D14: Số lượng tài sản
D15: Giá trị tài sản
D16: % Tài sản còn bảo hành
D17: % Tài sản sử dụng
C18: Biểu đồ tương tác (có thể hover xem chi tiết hoặc click chuyển sang module liên quan) | D18: Biểu đồ phân bổ tài sản dạng tròn
D19: Biểu đồ giá trị tài sản theo dạng cột
D20: Biểu đồ biến động tài sản theo thời gian dạng đường
D21: …
C22: Bộ lọc dữ liệu các nhóm tiêu chí | D22: Theo Phòng ban
D23: Theo nhóm/phân nhóm/tên tài sản
D24: Theo trạng thái tài sản
D25: Theo thời gian sử dụng
D26: Theo khoảng thời gian phát sinh
C27: Cho phép xuất dữ liệu Dashboard ra file excel
B31: 1 | C31: 2 | D31: 3 | E31: 4
B32: Content | D32: Value | E32: Type of chart | F32: Note
B33: 1. Dashboard tổng quan | C33: 1. Total assets | D33: Count số lượng (All tài sản - Đã thanh lý - Vô hiệu hóa)
C34: 2. Total value | D34: Sum nguyên giá (All tài sản - Đã thanh lý - Vô hiệu hóa)
C35: 3. Warranty status | D35: Tỷ lệ phần trăm theo số lượng tài sản còn hạn bảo hành/(All tài sản - Vô hiệu hóa - Đã thanh lý)
C36: 4. Utilization rate | D36: Tỷ lệ phần trăm theo số lượng tài sản có trạng thái đang sử dụng/(All tài sản - Vô hiệu hóa - Đã thanh lý)
B38: 2. Bộ lọc dùng chung | C38: 1. Vùng | D38: LOV
C39: 2. Đơn vị sử dụng | D39: LOV đồng bộ từ OMS
C40: 3. CAT 1 | D40: LOV
C41: 4. Group name | D41: LOV
C42: 5. Asset status | D42: LOV asset status (Không bao gồm Đã thanh lý, Vô hiệu hóa)
B44: 3. Chart | C44: 1. Asset Distribution
C45: - Cơ cấu nhóm tài sản theo trạng thái tài sản | D45: Nguyên giá | E45: Sunburst - Vòng trong: Nhóm IT/ADM/CMD - Vòng ngoài: Trạng thái | F45: Khi Hover chuột thể hiện số lượng, và giá trị
C46: - Cơ cấu nhóm tài sản theo Vùng, theo Đơn vị sử dụng | D46: Nguyên giá | E46: Stacked Column
C47: 2. Asset Value by Group Name | D47: Nguyên giá | E47: Column
C48: 3. Asset Fluctuation Over Time (Month/Year) | D48: Nguyên giá | E48: Line
...

Sheet 5
B2: MODULE QUẢN LÝ KHO
D5: As - is | F5: To - be | I5: BRD
B6: Process | D6: Step | E6: Role | F6: Step | G6: Role | H6: Note | I6: Function flow | J6: Details
B7: Điều chuyển | C7: Nội bộ
C8: Chéo
C9: Về kho | D9: 1. Tạo | E9: AMP/BU | F9: 1. Tạo | G9: AMP/BU User | I9: unchanged
D10: 2. Duyệt - Duyệt: chuyển bước 3 - Từ chối: về bước 1 | E10: BU Mgr | F10: 2. Duyệt - Duyệt: chuyển bước 3 - Từ chối: về bước 1 | G10: BU Mgr | I10: unchanged
D11: 3. Xác nhận điều chuyển - Xác nhận: Kết thúc luồng - Từ chối: về bước 1 | E11: AMP | F11: 3. Xác nhận điều chuyển - Xác nhận: kết thúc luồng, hệ thống auto tạo YC nhập kho - Từ chối: Về bước 1 | G11: AMP | I11: unchanged
B14: Nhập kho | F14: 1. Tạo YC nhập kho | G14: System | H14: System tạo thay cho AMP. YC nhập kho nằm trong DS Đã xử lý trong Menu Xuất nhập kho. Khi YC Nhập kho bị Từ chối, AMP có thể submit tiếp / Cancel YC nhập kho. Nếu cancel YC nhập kho, hệ thống tự động cancel YC Đ/C về kho. | I14: 5.1.1a | J14: 5.1.1b
F15: 2. Tiếp nhận, duyệt: - Duyệt: chuyển bước 3 - Từ chối: về bước 1 | G15: Warehouse Mgr | H15: TH Từ chối, YC về bước 1. AMP view đc các YC nhập kho và action như người khởi tạo YC nhập kho | I15: 5.1.2a | J15: 5.1.2b
F16: 3. Tiếp nhận hàng hóa: - Duyệt: kết thúc luồng, hệ thống update kết quả cho YC ĐC về kho - Từ chối: về bước 1 | G16: WK | H16: TH Từ chối, YC về bước 1. AMP view đc các YC nhập kho và action như người khởi tạo YC nhập kho. AMP có thể submit tiếp / Cancel YC nhập kho. Trường hợp AMP cancel YC nhập kho, hệ thống tự động cancel YC điều chuyển về ko | I16: 5.1.3a | J16: 5.1.3b
B18: Nhập kho thủ công | F18: 1. Tạo YC nhập kho | G18: AMP | I18: 5.2.1a | J18: 5.2.1b
F19: 2. Tiếp nhận, duyệt: - Duyệt: chuyển bước 3 - Từ chối: về bước 1 | G19: Warehouse Mgr | I19: 5.2.2a | J19: 5.2.2b
F20: 3. Tiếp nhận hàng hóa: - Duyệt: kết thúc luồng. - Từ chối: về bước 1 | G20: WK | I20: 5.2.3a | J20: 5.2.3b
B21: Hủy nhập kho | F21: 1. Nhập thông tin tìm kiếm yêu cầu | G21: AMP | I21: 5.3.1a | J21: 5.3.1b
F22: 2. Hiển thị kết quả | G22: System
F23: 3. Chọn, xem yêu cầu - Hủy: Kết thúc luồng | G23: AMP | H23: Update RQ điều chuyển sang trạng thái Đã hủy
F24: - Thoát
B26: Cấp TS | D26: 1. Tạo YC | E26: AMP | F26: 1. Tạo YC | G26: AMP | I26: unchanged
D27: 2. Xác nhận - Xác nhận: kết thúc luồng - Từ chối: về bước 1 | E27: BU User | F27: 2. Duyệt cấp TS - Duyệt: Kết thúc luồng. Hệ thống auto tạo YC xuất kho - Từ chối: Về bước 1 | G27: AM | I27: 5.4.0a | J27: 5.4.0b
B29: Thanh lý TS | D29: 1. Tạo YC | E29: AMP/BU User | F29: 1. Tạo YC | G29: AMP/BU User | I29: unchanged
D30: 2. Kiểm soát | E30: Checker | F30: 2. Kiểm soát | G30: Checker | I30: unchanged
D31: 3. Duyệt chủ trương | E31: Approver | F31: 3. Duyệt chủ trương | G31: Approver | I31: unchanged
D32: 4. Thanh lý TS (manual) | E32: AMP/BU User | F32: 4. Thanh lý TS (manual) | G32: AMP/BU User | I32: unchanged
D33: 5. Cập nhật kết quả TL | E33: AMP/BU User | F33: 5. Cập nhật kết quả TL: - Bid: chuyển bước 6, - Direct: Kết thúc luồng. Hệ thống auto tạo YC xuất kho. | G33: AMP/BU User | I33: unchanged
D34: 6. Kiểm soát | E34: Checker | F34: 6. Kiểm soát | G34: Checker | I34: unchanged
D35: 7. Duyệt KQ TL | E35: Approver | F35: 7. Duyệt KQ TL - Duyệt: Kết thúc luồng. Hệ thống auto tạo YC xuất kho - Từ chối: Về bước 5 | G35: Approver | I35: unchanged
B38: Xuất kho | F38: 1. Tạo YC xuất kho | G38: System | H38: System tạo thay cho AMP. YC xuất kho nằm trong DS Đã xử lý trong Menu Xuất nhập kho. Khi YC Xuất kho bị Từ chối, AMP có thể cancel YC Xuất kho. Khi Cancel YC xuất kho, hệ thống sẽ auto cancel YC Thanh lý TS, YC Cấp TS | I38: 5.4.1a | J38: 5.4.1b
F39: 2. Nhận YC xuất kho: - Xác nhận: Chuyển bước 3 - Từ chối: về bước 1 | G39: WK | H39: TH Từ chối, YC về bước 1. AMP view đc các YC xuất kho và action như người khởi tạo YC xuất kho. Trong YC xuất kho: - YC xuất kho link từ YC thanh lý: Không có nút Từ chối. Chỉ có nút: Xác nhận - YC xuất kho link từ YC cấp TS: Có nút Xác nhận, Từ chối | I39: 5.4.2a | J39: 5.4.2b
F40: 3. Duyệt: - Duyệt: chuyển bước 4 - Từ chối: Về bước 1 | G40: Warehouse Mgr | I40: 5.4.3a | J40: 5.4.3b
F41: 4. Xuất hàng (manual task) | G41: WK
F42: 5. Nhận hàng xuất kho - Xác nhận: kết thúc luồng. Hệ thống auto update kết quả cho YC Thanh lý, YC Cấp TS - Từ chối: Về bước 1 | G42: BU User | I42: 5.4.4a | J42: 5.4.4b
B43: Hủy xuất kho | F43: 1. Nhập thông tin tìm kiếm yêu cầu | G43: AMP | I43: 5.5.1a | J43: 5.5.1b
F44: 2. Hiển thị kết quả | G44: System
F45: 3. Chọn, xem yêu cầu - Hủy: Kết thúc luồng | G45: AMP
F46: - Thoát
B48: Điều chuyển kho | F48: 1. Tạo YC điều chuyển kho | G48: AMP | I48: 5.6.1a | J48: 5.6.1b
F49: 2. Duyệt YC điều chuyển kho: - Duyệt: chuyển bước 3 - Từ chối: về bước 1 | G49: AM, Warehouse Mgr | I49: 5.6.2a | J49: 5.6.2b
F50: 3. Xuất kho | G50: WK (kho đi) | H50: Hệ thống tự động generate biên bản xuất kho, bút toán xuất kho
F51: 4. Nhập kho | G51: WK (kho đến) | H51: Hệ thống tự động generate biên bản nhập kho, bút toán nhập kho

Sheet 5.1.1a
A1: <<<
B2: ĐIỀU CHUYỂN VỀ KHO
B3: Tạo yêu cầu nhập kho

Sheet 5.1.1b
A1: <<<
B2: ĐIỀU CHUYỂN VỀ KHO
B3: ='5.1.1a'!B3 -> Tạo yêu cầu nhập kho
B5: 1 | C5: 2 | E5: 1 | F5: =E5+1 -> 2 | G5: =F5+1 -> 3 | H5: =G5+1 -> 4 | I5: =H5+1 -> 5 | J5: =I5+1 -> 6 | K5: =J5+1 -> 7 | L5: =K5+1 -> 8 | M5: =L5+1 -> 9 | ... U5: =T5+1 -> 17
B6: 1. Tạo yêu cầu nhập kho | C6: 1 | E6: Data | R6: Status | S6: Notification | T6: Template | U6: Biz rule
C7: 2 | E7: Tab/section | F7: Operator | G7: Action | H7: Field name VN | I7: M/O | J7: Field type | K7: Editable | L7: Max length | M7: Format | N7: Default value | O7: LOV | P7: Data source | Q7: Data rule
C8: Hệ thống | E8: Hệ thống tự tạo yêu cầu nhập kho
E9: Thông tin chung
F10: System | G10: Display | H10: Số yêu cầu | I10: M | J10: Text | K10: N | L10: 50 | M10: NK.YY.xxxx | Q10: YY = Year, xxxx = số chạy từ 1-9999 không dùng lại
F11: System | G11: Display | H11: Ngày tạo | I11: M | J11: Date | K11: N | L11: 50 | M11: MM.DD.YYYY | N11: Today
F12: System | G12: Display | H12: Tiêu đề | I12: M | J12: Text | K12: N | L12: 150 | Q12: =Tiêu đề RQ điều chuyển
E13: DS tài sản nhập kho | Q13: = Tài sản từ RQ điều chuyển
F14: System | G14: Display | H14: Mã tài sản | I14: M | K14: N | Q14: Hiển thị mặc định
F15: System | G15: Display | H15: Tên Tài sản | I15: M | K15: N | Q15: Hiển thị mặc định
F16: System | G16: Display | H16: Mô tả TS | I16: M | K16: N | Q16: Hiển thị mặc định
F17: System | G17: Display | H17: Trạng thái TS | I17: M | K17: N | Q17: Hiển thị mặc định
F18: System | G18: Display | H18: Phân nhóm TS (group name) | I18: M | K18: N | Q18: Hiển thị mặc định
F19: System | G19: Display | H19: Nhóm TS (CAT1) | I19: M | K19: N | Q19: Hiển thị mặc định
F20: System | G20: Display | H20: Số PO | I20: M | K20: N | Q20: Hiển thị mặc định
F21: System | G21: Display | H21: Tên nhà cung cấp | I21: O | K21: N | Q21: Ẩn hiện tùy biến
F22: System | G22: Display | H22: Nguyên giá TS (VAT incl) | I22: M | K22: N | Q22: Ẩn hiện tùy biến
F23: System | G23: Display | H23: Mã TS liên quan | I23: O | K23: N | Q23: Ẩn hiện tùy biến
F24: System | G24: Display | H24: Mô tả TS liên quan | I24: O | K24: N | Q24: Ẩn hiện tùy biến
F25: System | G25: Display | H25: Tên người sử dụng | I25: M | K25: N | Q25: Hiển thị mặc định
... F39: System | G39: Display | H39: Ngày bắt đầu sử dụng | I39: O | K39: N | Q39: Ẩn hiện tùy biến
E40: Thông tin kho nhập
F41: System | G41: Display | H41: Tên kho | I41: M | J41: List | K41: N | L41: 50 | Q41: = Kho trong RQ điều chuyển
F42: System | G42: Display | H42: Địa chỉ kho | I42: M | J42: Text | K42: N | L42: 50 | P42: OMS | Q42: Tự động nhận diện, hiển thị theo Tên kho
F43: System | G43: Display | H43: Quản lý kho | I43: M | J43: Text | K43: N | L43: 50 | P43: OMS | Q43: Tự động nhận diện, hiển thị theo Tên kho (Tên | Phòng ban | Email)
E44: Thông tin đầu mối giao hàng
F45: User | G45: Input | H45: Đầu mối | I45: M | J45: Text | K45: N | L45: 50 | Q45: = Đầu mối giao hàng tròng RQ điều chuyển
F46: User | G46: Input | H46: Số điện thoại | I46: M | J46: Number | K46: N | L46: 52
F47: User | G47: Input | H47: Thời gian bàn giao | I47: O | J47: Date | K47: N | L47: 50
E48: Ghi chú | F48: User | G48: Input | H48: Ghi chú | I48: M | J48: Text | K48: N | L48: 150 | Q48: = SỐ RQ điều chuyển
E49: Hồ sơ đính kèm | Q49: =Hồ sơ đính kèm trong RQ điều chuyển
F50: User | G50: Select | H50: Thêm | I50: M | J50: Button | K50: N
F51: User | G51: Select | H51: File | I51: M | K51: N
F52: System/User | G52: Display/Select | H52: Tên thư mục | I52: M | K52: N
F53: System/User | G53: Display/Input | H53: Tên tài liệu | I53: M | J53: Text | K53: N | L53: 150
F54: System | G54: Display | H54: Ngày | I54: M | K54: N
...

Sheet 5.1.1b (2)
A1: <<<
B2: ĐIỀU CHUYỂN VỀ KHO
B3: =#REF! -> #REF!
B5: 1 | C5: 2 | E5: 1 | F5: =E5+1 -> 2 | G5: =F5+1 -> 3 | H5: =G5+1 -> 4 | I5: =H5+1 -> 5 | J5: =I5+1 -> 6 | K5: =J5+1 -> 7 | L5: =K5+1 -> 8 | M5: =L5+1 -> 9 | ... U5: =T5+1 -> 17
B6: 1. Nhập thông tin tìm kiếm yêu cầu | C6: 1 | E6: Data | R6: Status | S6: Notification | T6: Template | U6: Biz rule
C7: 2 | E7: Tab/section | F7: Operator | G7: Action | H7: Field name VN | I7: M/O | J7: Field type | K7: Editable | L7: Max length | M7: Format | N7: Default value | O7: LOV | P7: Data source | Q7: Data rule
C8: AMP | E8: Tìm kiếm yêu cầu
F9: User | G9: Input | H9: Mã yêu cầu | I9: O | J9: Text | K9: Y | L9: 20
F10: User | G10: Input | H10: Tiêu đề | I10: O | J10: Text | K10: Y | L10: 100
F11: User | G11: Select | H11: Người xử lý | I11: O | J11: List | K11: Y | L11: 20
F12: User | G12: Select | H12: Loại điều chuyển | I12: O | J12: List | K12: Y | L12: 20
F13: User | G13: Select | H13: Trạng thái | I13: O | J13: List | K13: Y | L13: 20
F14: User | G14: Select | H14: Người tạo | I14: O | J14: List | K14: Y | L14: 20
F15: User | G15: Select | H15: Người đề xuất | I15: O | J15: List | K15: Y | L15: 20
F16: User | G16: Input | H16: Ngày tạo | I16: O | J16: Date | K16: Y | L16: 50
F17: User | G17: Select | H17: Đơn vị điều chuyển | I17: O | J17: List | K17: Y | L17: 50
F18: User | G18: Select | H18: Đơn vị nhận điều chuyển | I18: O | J18: List | K18: Y | L18: 50
B19: 2. Hiển thị kết quả tìm kiếm | C19: Hệ thống | E19: Danh sách yêu cầu
F20: System | G20: Display | H20: Mã yêu cầu | I20: M | J20: Text | K20: N | L20: 20
F21: System | G21: Display | H21: Tiêu đề | I21: M | J21: Text | K21: N | L21: 100
F22: System | G22: Display | H22: Người tạo | I22: M | J22: Text | K22: N | L22: 20
F23: System | G23: Display | H23: Trạng thái | I23: M | J23: Text | K23: N | L23: 20
F24: System | G24: Display | H24: Loại điều chuyển | I24: M | J24: Text | K24: N | L24: 20
F25: System | G25: Display | H25: Người xử lý | I25: O | J25: Text | K25: N | L25: 20
F26: System | G26: Display | H26: Đơn vị điều chuyển | I26: O | J26: Text | K26: N | L26: 20
F27: System | G27: Display | H27: Đơn vị nhận điều chuyển | I27: O | J27: Text | K27: N | L27: 50
B29: 3. Chọn yêu cầu, xem | C29: AMP | F29: User | G29: Select | H29: Yêu cầu
E30: Thông tin chung
F31: System | G31: Display | H31: Loại điều chuyển | I31: M | J31: Text | K31: N
F32: System | G32: Display | H32: Số yêu cầu | I32: M | J32: Text | K32: N
F33: System | G33: Display | H33: Ngày tạo | I33: M | J33: Date | K33: N
F34: System | G34: Display | H34: Tiêu đề | I34: M | J34: Text | K34: N
E35: DS tài sản
F36: System | G36: Display | H36: Mã tài sản | I36: M | K36: N
F37: System | G37: Display | H37: Tên Tài sản | I37: M | K37: N
F38: System/User | G38: Display/Edit | H38: Mô tả TS | I38: M | K38: N
F39: System | G39: Display | H39: Phân nhóm TS (group name) | I39: M | K39: N
F40: System | G40: Display | H40: Nhóm TS (CAT1) | I40: M | K40: N
F41: System | G41: Display | H41: Mã TS liên quan | I41: O | K41: N
F42: System | G42: Display | H42: Mô tả TS liên quan | I42: O | K42: N
...

Sheet 5.1.2a
A1: <<<
B2: ĐIỀU CHUYỂN VỀ KHO
B3: Phê duyệt yêu cầu nhập kho

Sheet 5.1.2b
A1: <<<
B2: ='5.1.2a'!B2 -> ĐIỀU CHUYỂN VỀ KHO
B3: ='5.1.2a'!B3 -> Phê duyệt yêu cầu nhập kho
B5: 1 | C5: 2 | E5: 1 | F5: =E5+1 -> 2 | G5: =F5+1 -> 3 | H5: =G5+1 -> 4 | I5: =H5+1 -> 5 | J5: =I5+1 -> 6 | K5: =J5+1 -> 7 | L5: =K5+1 -> 8 | M5: =L5+1 -> 9 | ... U5: =T5+1 -> 17
B6: 1. Nhập thông tin tìm kiếm yêu cầu | C6: 1 | E6: Data | R6: Status | S6: Notification | T6: Template | U6: Biz rule
C7: 2 | E7: Tab/section | F7: Operator | G7: Action | H7: Field name VN | I7: M/O | J7: Field type | K7: Editable | L7: Max length | M7: Format | N7: Default value | O7: LOV | P7: Data source | Q7: Data rule
C8: Warehouse Mgr. | E8: Tìm kiếm yêu cầu
F9: User | G9: Input | H9: Số yêu cầu | I9: O | J9: Text | K9: Y | L9: 20
F10: User | G10: Input | H10: Ngày tạo | I10: O | J10: Date | K10: Y | L10: 20
F11: User | G11: Input | H11: Tiêu đề | I11: O | J11: Text | K11: Y | L11: 150
F12: User | G12: Select | H12: Người tạo | I12: O | J12: List | K12: Y | L12: 20
F13: User | G13: Select | H13: Trạng thái yêu cầu | I13: O | J13: List | K13: Y | L13: 20
F14: User | G14: Select | H14: Người xử lý | I14: O | J14: List | K14: Y | L14: 20
F15: User | G15: Input | H15: Ngày xác nhận | I15: O | J15: Date | K15: Y | L15: 20
B16: 2. Hiển thị kết quả tìm kiếm | C16: Hệ thống | E16: Danh sách yêu cầu
F17: System | G17: Display | H17: Số yêu cầu | I17: M | J17: Text | K17: N | L17: 20
F18: System | G18: Display | H18: Ngày tạo | I18: M | J18: Date | K18: N | L18: 20
F19: System | G19: Display | H19: Tiêu đề | I19: M | J19: Text | K19: N | L19: 150
F20: System | G20: Display | H20: Người tạo | I20: M | J20: Text | K20: N | L20: 20
F21: System | G21: Display | H21: Trạng thái yêu cầu | I21: M | J21: Text | K21: N | L21: 20
F22: System | G22: Display | H22: Người xử lý | I22: O | J22: Text | K22: N | L22: 20
F23: System | G23: Display | H23: Ngày xác nhận | I23: O | J23: Date | K23: N | L23: 20
B24: 3. Chọn yêu cầu, xem | C24: Warehouse Mgr. | F24: User | G24: Select | H24: Yêu cầu
E25: Thông tin chung
F26: System | G26: Display | H26: Số yêu cầu | I26: M | J26: Text | K26: N
F27: System | G27: Display | H27: Ngày tạo | I27: M | J27: Date | K27: N
F28: System | G28: Display | H28: Tiêu đề | I28: M | J28: Text | K28: N
E29: DS tài sản nhập kho
F30: System | G30: Display | H30: Mã tài sản | I30: M | K30: N | Q30: Hiển thị mặc định
F31: System | G31: Display | H31: Tên Tài sản | I31: M | K31: N | Q31: Hiển thị mặc định
F32: System | G32: Display | H32: Mô tả TS | I32: M | K32: N | Q32: Hiển thị mặc định
F33: System | G33: Display | H33: Trạng thái TS | I33: M | K33: N | Q33: Hiển thị mặc định
F34: System | G34: Display | H34: Phân nhóm TS (group name) | I34: M | K34: N | Q34: Hiển thị mặc định
F35: System | G35: Display | H35: Nhóm TS (CAT1) | I35: M | K35: N | Q35: Hiển thị mặc định
F36: System | G36: Display | H36: Số PO | I36: M | K36: N | Q36: Hiển thị mặc định
F37: System | G37: Display | H37: Tên nhà cung cấp | I37: O | K37: N | Q37: Ẩn hiện tùy biến
F38: System | G38: Display | H38: Nguyên giá TS (VAT incl) | I38: M | K38: N | Q38: Ẩn hiện tùy biến
F39: System | G39: Display | H39: Mã TS liên quan | I39: O | K39: N | Q39: Ẩn hiện tùy biến
F40: System | G40: Display | H40: Mô tả TS liên quan | I40: O | K40: N | Q40: Ẩn hiện tùy biến
F41: System | G41: Display | H41: Tên người sử dụng | I41: M | K41: N | Q41: Hiển thị mặc định
...

Sheet 5.1.3a
A1: <<<
B2: NHẬP KHO TỪ QUY TRÌNH ĐIỀU CHUYỂN VỀ KHO
B3: Xác nhận nhập kho

Sheet 5.1.3b
A1: <<<
B2: NHẬP KHO TỪ QUY TRÌNH ĐIỀU CHUYỂN VỀ KHO
B3: Xác nhận nhập kho
B5: 1 | C5: 2 | E5: 1 | F5: =E5+1 -> 2 | G5: =F5+1 -> 3 | H5: =G5+1 -> 4 | I5: =H5+1 -> 5 | J5: =I5+1 -> 6 | K5: =J5+1 -> 7 | L5: =K5+1 -> 8 | M5: =L5+1 -> 9 | ... U5: =T5+1 -> 17
B6: 1. Nhập thông tin tìm kiếm yêu cầu | C6: 1 | E6: Data | R6: Status | S6: Notification | T6: Template | U6: Biz rule
C7: 2 | E7: Tab/section | F7: Operator | G7: Action | H7: Field name VN | I7: M/O | J7: Field type | K7: Editable | L7: Max length | M7: Format | N7: Default value | O7: LOV | P7: Data source | Q7: Data rule
C8: WK | E8: Tìm kiếm yêu cầu
F9: User | G9: Input | H9: Số yêu cầu | I9: O | J9: Text | K9: Y | L9: 20
F10: User | G10: Input | H10: Ngày tạo | I10: O | J10: Date | K10: Y | L10: 20
F11: User | G11: Input | H11: Tiêu đề | I11: O | J11: Text | K11: Y | L11: 150
F12: User | G12: Select | H12: Người tạo | I12: O | J12: List | K12: Y | L12: 20
F13: User | G13: Select | H13: Trạng thái yêu cầu | I13: O | J13: List | K13: Y | L13: 20
F14: User | G14: Select | H14: Người xử lý | I14: O | J14: List | K14: Y | L14: 20
F15: User | G15: Input | H15: Ngày xác nhận | I15: O | J15: Date | K15: Y | L15: 20
B16: 2. Hiển thị kết quả tìm kiếm | C16: Hệ thống | E16: Danh sách yêu cầu
F17: System | G17: Display | H17: Số yêu cầu | I17: M | J17: Text | K17: N | L17: 20
F18: System | G18: Display | H18: Ngày tạo | I18: M | J18: Date | K18: N | L18: 20
F19: System | G19: Display | H19: Tiêu đề | I19: M | J19: Text | K19: N | L19: 150
F20: System | G20: Display | H20: Người tạo | I20: M | J20: Text | K20: N | L20: 20
F21: System | G21: Display | H21: Trạng thái yêu cầu | I21: M | J21: Text | K21: N | L21: 20
F22: System | G22: Display | H22: Người xử lý | I22: O | J22: Text | K22: N | L22: 20
F23: System | G23: Display | H23: Ngày xác nhận | I23: O | J23: Date | K23: N | L23: 20
B24: 3. Chọn yêu cầu, xem | C24: WK | F24: User | G24: Select | H24: Yêu cầu
E25: Thông tin chung
F26: System | G26: Display | H26: Số yêu cầu | I26: M | J26: Text | K26: N
F27: System | G27: Display | H27: Ngày tạo | I27: M | J27: Date | K27: N
F28: System | G28: Display | H28: Tiêu đề | I28: M | J28: Text | K28: N
E29: DS tài sản nhập kho
F30: System | G30: Display | H30: Mã tài sản | I30: M | K30: N | Q30: Hiển thị mặc định
F31: System | G31: Display | H31: Tên Tài sản | I31: M | K31: N | Q31: Hiển thị mặc định
F32: System | G32: Display | H32: Mô tả TS | I32: M | K32: N | Q32: Hiển thị mặc định
F33: System | G33: Display | H33: Trạng thái TS | I33: M | K33: N | Q33: Hiển thị mặc định
F34: System | G34: Display | H34: Phân nhóm TS (group name) | I34: M | K34: N | Q34: Hiển thị mặc định
F35: System | G35: Display | H35: Nhóm TS (CAT1) | I35: M | K35: N | Q35: Hiển thị mặc định
F36: System | G36: Display | H36: Số PO | I36: M | K36: N | Q36: Hiển thị mặc định
F37: System | G37: Display | H37: Tên nhà cung cấp | I37: O | K37: N | Q37: Ẩn hiện tùy biến
F38: System | G38: Display | H38: Nguyên giá TS (VAT incl) | I38: M | K38: N | Q38: Ẩn hiện tùy biến
F39: System | G39: Display | H39: Mã TS liên quan | I39: O | K39: N | Q39: Ẩn hiện tùy biến
F40: System | G40: Display | H40: Mô tả TS liên quan | I40: O | K40: N | Q40: Ẩn hiện tùy biến
F41: System | G41: Display | H41: Tên người sử dụng | I41: M | K41: N | Q41: Hiển thị mặc định
...

Sheet 5.2.1a
A1: <<<
B2: NHÂP KHO THỦ CÔNG
B3: Tạo yêu cầu

Sheet 5.2.1b
A1: <<<
B2: ='5.2.1a'!B2 -> NHÂP KHO THỦ CÔNG
B3: ='5.2.1a'!B3 -> Tạo yêu cầu
B5: 1 | C5: 2 | E5: 1 | F5: 2 | G5: 3 | H5: 4 | I5: 5 | J5: 6 | K5: 7 | L5: 8 | M5: 9 | N5: 10 | O5: 11 | P5: 12 | Q5: 13 | R5: 14 | S5: 15 | T5: 16 | U5: 17
B6: 1. Tạo yêu cầu, đính kèm, xem lại yêu cầu | C6: 1 | E6: Data | R6: Status | S6: Notification | T6: Template | U6: Biz rule
C7: 2 | E7: Tab/section | F7: Operator | G7: Action | H7: Field name VN | I7: M/O | J7: Field type | K7: Editable | L7: Max length | M7: Format | N7: Default value | O7: LOV | P7: Data source | Q7: Data rule
C8: AMP | F8: User | G8: Select | H8: Tạo | I8: M | J8: Button | K8: N
E9: Thông tin chung
F10: System | G10: Display | H10: Số yêu cầu | I10: M | J10: Text | K10: N | L10: 50 | M10: NK.YY.xxxx | Q10: YY = Year, xxxx = số chạy từ 1-9999 không dùng lại
F11: System | G11: Display | H11: Ngày tạo | I11: M | J11: Date | K11: N | L11: 50 | M11: MM.DD.YYYY | N11: Today
F12: User | G12: Input | H12: Tiêu đề | I12: O | J12: Text | K12: Y | L12: 150
F13: User | G13: Select | H13: Thêm tài sản | I13: M | J13: Button | K13: N
E14: Tìm kiếm tài sản
F15: User | G15: Input | H15: Mã tài sản | I15: O | J15: Text | K15: N | L15: 20
F16: User | G16: Input | H16: Tên tài sản | I16: O | J16: Text | K16: Y | L16: 20
F17: User | G17: Select | H17: Phân loại tài sản | I17: O | J17: List | K17: N | L17: 20
F18: User | G18: Select | H18: Nhóm tài sản | I18: O | J18: List | K18: N | L18: 20
F19: User | G19: Input | H19: PO number | I19: O | J19: Text | K19: Y | L19: 20
F20: User | G20: Select | H20: Trạng thái TS | I20: O | J20: List | K20: N | L20: 50
F21: User | G21: Select | H21: Tên nhà cung cấp | I21: O | J21: List | K21: N | L21: 50
F22: User | G22: Input | H22: Tên kho | I22: O | J22: List | K22: Y | L22: 50
F23: User | G23: Select | H23: Vị trí đặt tài sản | I23: O | J23: Text | K23: N | L23: 100
E24: DS kết quả tìm kiếm
F25: System | G25: Display | H25: Mã tài sản | I25: M | K25: N | Q25: Hiển thị mặc định
F26: System | G26: Display | H26: Tên Tài sản | I26: M | K26: N | Q26: Hiển thị mặc định
F27: System | G27: Display | H27: Mô tả TS | I27: M | K27: N | Q27: Hiển thị mặc định
F28: System | G28: Display | H28: Trạng thái TS | I28: M | K28: N | Q28: Hiển thị mặc định
F29: System | G29: Display | H29: Phân nhóm TS (group name) | I29: M | K29: N | Q29: Hiển thị mặc định
F30: System | G30: Display | H30: Nhóm TS (CAT1) | I30: M | K30: N | Q30: Hiển thị mặc định
F31: System | G31: Display | H31: Số PO | I31: M | K31: N | Q31: Hiển thị mặc định
F32: System | G32: Display | H32: Tên nhà cung cấp | I32: O | K32: N | Q32: Ẩn hiện tùy biến
F33: System | G33: Display | H33: Nguyên giá TS (VAT incl) | I33: M | K33: N | Q33: Ẩn hiện tùy biến
F34: System | G34: Display | H34: Mã TS liên quan | I34: O | K34: N | Q34: Ẩn hiện tùy biến
F35: System | G35: Display | H35: Mô tả TS liên quan | I35: O | K35: N | Q35: Ẩn hiện tùy biến
F36: System | G36: Display | H36: Tên người sử dụng | I36: M | K36: N | Q36: Hiển thị mặc định
... F51: User | G51: Select/Add | H51: Tài sản | I51: M | K51: N | Q51: Có thể chọn nhiều TS. Cảnh báo khi tài sản chọn bị lock trong 1 on-going request
E52: DS tài sản nhập kho
F53: System | G53: Display | H53: Mã tài sản | I53: M | K53: N | Q53: Hiển thị mặc định
F54: System | G54: Display | H54: Tên Tài sản | I54: M | K54: N | Q54: Hiển thị mặc định
F55: System | G55: Display | H55: Mô tả TS | I55: M | K55: N | Q55: Hiển thị mặc định
...

Sheet 5.2.2a
A1: <<<
B2: ='5.2.1a'!B2 -> NHÂP KHO THỦ CÔNG
B3: Phê duyệt yêu cầu

Sheet 5.2.2b
A1: <<<
B2: ='5.2.1a'!B2 -> NHÂP KHO THỦ CÔNG
B3: Phê duyệt yêu cầu
B5: 1 | C5: 2 | E5: 1 | F5: =E5+1 -> 2 | G5: =F5+1 -> 3 | H5: =G5+1 -> 4 | I5: =H5+1 -> 5 | J5: =I5+1 -> 6 | K5: =J5+1 -> 7 | L5: =K5+1 -> 8 | M5: =L5+1 -> 9 | ... U5: =T5+1 -> 17
B6: 1. Nhập thông tin tìm kiếm yêu cầu | C6: 1 | E6: Data | R6: Status | S6: Notification | T6: Template | U6: Biz rule
C7: 2 | E7: Tab/section | F7: Operator | G7: Action | H7: Field name VN | I7: M/O | J7: Field type | K7: Editable | L7: Max length | M7: Format | N7: Default value | O7: LOV | P7: Data source | Q7: Data rule
C8: Warehouse Mgr. | E8: Tìm kiếm yêu cầu
F9: User | G9: Input | H9: Số yêu cầu | I9: O | J9: Text | K9: Y | L9: 20
F10: User | G10: Input | H10: Ngày tạo | I10: O | J10: Date | K10: Y | L10: 20
F11: User | G11: Input | H11: Tiêu đề | I11: O | J11: Text | K11: Y | L11: 150
F12: User | G12: Select | H12: Người tạo | I12: O | J12: List | K12: Y | L12: 20
F13: User | G13: Select | H13: Trạng thái yêu cầu | I13: O | J13: List | K13: Y | L13: 20
F14: User | G14: Select | H14: Người xử lý | I14: O | J14: List | K14: Y | L14: 20
F15: User | G15: Input | H15: Ngày xác nhận | I15: O | J15: Date | K15: Y | L15: 20
B16: 2. Hiển thị kết quả tìm kiếm | C16: Hệ thống | E16: Danh sách yêu cầu
F17: System | G17: Display | H17: Số yêu cầu | I17: M | J17: Text | K17: N | L17: 20
F18: System | G18: Display | H18: Ngày tạo | I18: M | J18: Date | K18: N | L18: 20
F19: System | G19: Display | H19: Tiêu đề | I19: M | J19: Text | K19: N | L19: 150
F20: System | G20: Display | H20: Người tạo | I20: M | J20: Text | K20: N | L20: 20
F21: System | G21: Display | H21: Trạng thái yêu cầu | I21: M | J21: Text | K21: N | L21: 20
F22: System | G22: Display | H22: Người xử lý | I22: O | J22: Text | K22: N | L22: 20
F23: System | G23: Display | H23: Ngày xác nhận | I23: O | J23: Date | K23: N | L23: 20
B24: 3. Chọn yêu cầu, xem | C24: Warehouse Mgr. | F24: User | G24: Select | H24: Yêu cầu
E25: Thông tin chung
F26: System | G26: Display | H26: Số yêu cầu | I26: M | J26: Text | K26: N
F27: System | G27: Display | H27: Ngày tạo | I27: M | J27: Date | K27: N
F28: System | G28: Display | H28: Tiêu đề | I28: M | J28: Text | K28: N
E29: DS tài sản nhập kho
F30: System | G30: Display | H30: Mã tài sản | I30: M | K30: N | Q30: Hiển thị mặc định
F31: System | G31: Display | H31: Tên Tài sản | I31: M | K31: N | Q31: Hiển thị mặc định
F32: System | G32: Display | H32: Mô tả TS | I32: M | K32: N | Q32: Hiển thị mặc định
F33: System | G33: Display | H33: Trạng thái TS | I33: M | K33: N | Q33: Hiển thị mặc định
F34: System | G34: Display | H34: Phân nhóm TS (group name) | I34: M | K34: N | Q34: Hiển thị mặc định
F35: System | G35: Display | H35: Nhóm TS (CAT1) | I35: M | K35: N | Q35: Hiển thị mặc định
F36: System | G36: Display | H36: Số PO | I36: M | K36: N | Q36: Hiển thị mặc định
F37: System | G37: Display | H37: Tên nhà cung cấp | I37: O | K37: N | Q37: Ẩn hiện tùy biến
F38: System | G38: Display | H38: Nguyên giá TS (VAT incl) | I38: M | K38: N | Q38: Ẩn hiện tùy biến
F39: System | G39: Display | H39: Mã TS liên quan | I39: O | K39: N | Q39: Ẩn hiện tùy biến
F40: System | G40: Display | H40: Mô tả TS liên quan | I40: O | K40: N | Q40: Ẩn hiện tùy biến
F41: System | G41: Display | H41: Tên người sử dụng | I41: M | K41: N | Q41: Hiển thị mặc định
...

Sheet 5.2.3a
A1: <<<
B2: ='5.2.1a'!B2 -> NHÂP KHO THỦ CÔNG
B3: Xác nhận nhập kho

Sheet 5.2.3b
A1: <<<
B2: ='5.2.1a'!B2 -> NHÂP KHO THỦ CÔNG
B3: Xác nhận nhập kho
B5: 1 | C5: 2 | E5: 1 | F5: =E5+1 -> 2 | G5: =F5+1 -> 3 | H5: =G5+1 -> 4 | I5: =H5+1 -> 5 | J5: =I5+1 -> 6 | K5: =J5+1 -> 7 | L5: =K5+1 -> 8 | M5: =L5+1 -> 9 | ... U5: =T5+1 -> 17
B6: 1. Nhập thông tin tìm kiếm yêu cầu | C6: 1 | E6: Data | R6: Status | S6: Notification | T6: Template | U6: Biz rule
C7: 2 | E7: Tab/section | F7: Operator | G7: Action | H7: Field name VN | I7: M/O | J7: Field type | K7: Editable | L7: Max length | M7: Format | N7: Default value | O7: LOV | P7: Data source | Q7: Data rule
C8: WK | E8: Tìm kiếm yêu cầu
F9: User | G9: Input | H9: Số yêu cầu | I9: O | J9: Text | K9: Y | L9: 20
F10: User | G10: Input | H10: Ngày tạo | I10: O | J10: Date | K10: Y | L10: 20
F11: User | G11: Input | H11: Tiêu đề | I11: O | J11: Text | K11: Y | L11: 150
F12: User | G12: Select | H12: Người tạo | I12: O | J12: List | K12: Y | L12: 20
F13: User | G13: Select | H13: Trạng thái yêu cầu | I13: O | J13: List | K13: Y | L13: 20
F14: User | G14: Select | H14: Người xử lý | I14: O | J14: List | K14: Y | L14: 20
F15: User | G15: Input | H15: Ngày xác nhận | I15: O | J15: Date | K15: Y | L15: 20
B16: 2. Hiển thị kết quả tìm kiếm | C16: Hệ thống | E16: Danh sách yêu cầu
F17: System | G17: Display | H17: Số yêu cầu | I17: M | J17: Text | K17: N | L17: 20
F18: System | G18: Display | H18: Ngày tạo | I18: M | J18: Date | K18: N | L18: 20
F19: System | G19: Display | H19: Tiêu đề | I19: M | J19: Text | K19: N | L19: 150
F20: System | G20: Display | H20: Người tạo | I20: M | J20: Text | K20: N | L20: 20
F21: System | G21: Display | H21: Trạng thái yêu cầu | I21: M | J21: Text | K21: N | L21: 20
F22: System | G22: Display | H22: Người xử lý | I22: O | J22: Text | K22: N | L22: 20
F23: System | G23: Display | H23: Ngày xác nhận | I23: O | J23: Date | K23: N | L23: 20
B24: 3. Chọn yêu cầu, xem | C24: WK | F24: User | G24: Select | H24: Yêu cầu
E25: Thông tin chung
F26: System | G26: Display | H26: Số yêu cầu | I26: M | J26: Text | K26: N
F27: System | G27: Display | H27: Ngày tạo | I27: M | J27: Date | K27: N
F28: System | G28: Display | H28: Tiêu đề | I28: M | J28: Text | K28: N
E29: DS tài sản nhập kho
F30: System | G30: Display | H30: Mã tài sản | I30: M | K30: N | Q30: Hiển thị mặc định
F31: System | G31: Display | H31: Tên Tài sản | I31: M | K31: N | Q31: Hiển thị mặc định
F32: System | G32: Display | H32: Mô tả TS | I32: M | K32: N | Q32: Hiển thị mặc định
F33: System | G33: Display | H33: Trạng thái TS | I33: M | K33: N | Q33: Hiển thị mặc định
F34: System | G34: Display | H34: Phân nhóm TS (group name) | I34: M | K34: N | Q34: Hiển thị mặc định
F35: System | G35: Display | H35: Nhóm TS (CAT1) | I35: M | K35: N | Q35: Hiển thị mặc định
F36: System | G36: Display | H36: Số PO | I36: M | K36: N | Q36: Hiển thị mặc định
F37: System | G37: Display | H37: Tên nhà cung cấp | I37: O | K37: N | Q37: Ẩn hiện tùy biến
F38: System | G38: Display | H38: Nguyên giá TS (VAT incl) | I38: M | K38: N | Q38: Ẩn hiện tùy biến
F39: System | G39: Display | H39: Mã TS liên quan | I39: O | K39: N | Q39: Ẩn hiện tùy biến
F40: System | G40: Display | H40: Mô tả TS liên quan | I40: O | K40: N | Q40: Ẩn hiện tùy biến
F41: System | G41: Display | H41: Tên người sử dụng | I41: M | K41: N | Q41: Hiển thị mặc định
...

Sheet 5.3.1a
A1: <<<
B2: HỦY YÊU CẦU NHẬP KHO

Sheet 5.3.1b
A1: <<<
B2: HỦY YÊU CẦU NHẬP KHO
B3: Điều kiện: | C3: 1. Yêu cầu nhập kho gửi đi thành công, có trạng thái <> "Đã nhập kho"
B6: 1 | C6: 2 | E6: 1 | F6: =E6+1 -> 2 | G6: =F6+1 -> 3 | H6: =G6+1 -> 4 | I6: =H6+1 -> 5 | J6: =I6+1 -> 6 | K6: =J6+1 -> 7 | L6: =K6+1 -> 8 | M6: =L6+1 -> 9 | ... U6: =T6+1 -> 17
B7: 1. Nhập thông tin tìm kiếm yêu cầu | C7: 1 | E7: Data | R7: Status | S7: Notification | T7: Template | U7: Biz rule
C8: 2 | E8: Tab/section | F8: Operator | G8: Action | H8: Field name VN | I8: M/O | J8: Field type | K8: Editable | L8: Max length | M8: Format | N8: Default value | O8: LOV | P8: Data source | Q8: Data rule
C9: AMP | E9: Tìm kiếm yêu cầu
F10: User | G10: Input | H10: Số yêu cầu | I10: O | J10: Text | K10: Y | L10: 20
F11: User | G11: Input | H11: Ngày tạo | I11: O | J11: Date | K11: Y | L11: 20
F12: User | G12: Input | H12: Tiêu đề | I12: O | J12: Text | K12: Y | L12: 150
F13: User | G13: Select | H13: Người tạo | I13: O | J13: List | K13: Y | L13: 20
F14: User | G14: Select | H14: Trạng thái yêu cầu | I14: O | J14: List | K14: Y | L14: 20
F15: User | G15: Select | H15: Người xử lý | I15: O | J15: List | K15: Y | L15: 20
F16: User | G16: Input | H16: Ngày xác nhận | I16: O | J16: Date | K16: Y | L16: 20
B17: 2. Hiển thị kết quả tìm kiếm | C17: Hệ thống | E17: Danh sách yêu cầu
F18: System | G18: Display | H18: Số yêu cầu | I18: M | J18: Text | K18: N | L18: 20
F19: System | G19: Display | H19: Ngày tạo | I19: M | J19: Date | K19: N | L19: 20
F20: System | G20: Display | H20: Tiêu đề | I20: M | J20: Text | K20: N | L20: 150
F21: System | G21: Display | H21: Người tạo | I21: M | J21: Text | K21: N | L21: 20
F22: System | G22: Display | H22: Trạng thái yêu cầu | I22: M | J22: Text | K22: N | L22: 20
F23: System | G23: Display | H23: Người xử lý | I23: O | J23: Text | K23: N | L23: 20
F24: System | G24: Display | H24: Ngày xác nhận | I24: O | J24: Date | K24: N | L24: 20
B25: 3. Chọn yêu cầu, xem | C25: AMP | F25: User | G25: Select | H25: Yêu cầu
E26: Thông tin chung
F27: System | G27: Display | H27: Số yêu cầu | I27: M | J27: Text | K27: Y
F28: System | G28: Display | H28: Ngày tạo | I28: M | J28: Date | K28: N
F29: System | G29: Display | H29: Tiêu đề | I29: M | J29: Text | K29: Y
E30: DS tài sản nhập kho
F31: System | G31: Display | H31: Mã tài sản | I31: M | K31: N | Q31: Hiển thị mặc định
F32: System | G32: Display | H32: Tên Tài sản | I32: M | K32: N | Q32: Hiển thị mặc định
F33: System | G33: Display | H33: Mô tả TS | I33: M | K33: N | Q33: Hiển thị mặc định
F34: System | G34: Display | H34: Trạng thái TS | I34: M | K34: N | Q34: Hiển thị mặc định
F35: System | G35: Display | H35: Phân nhóm TS (group name) | I35: M | K35: N | Q35: Hiển thị mặc định
F36: System | G36: Display | H36: Nhóm TS (CAT1) | I36: M | K36: N | Q36: Hiển thị mặc định
F37: System | G37: Display | H37: Số PO | I37: M | K37: N | Q37: Hiển thị mặc định
F38: System | G38: Display | H38: Tên nhà cung cấp | I38: O | K38: N | Q38: Ẩn hiện tùy biến
F39: System | G39: Display | H39: Nguyên giá TS (VAT incl) | I39: M | K39: N | Q39: Ẩn hiện tùy biến
F40: System | G40: Display | H40: Mã TS liên quan | I40: O | K40: N | Q40: Ẩn hiện tùy biến
F41: System | G41: Display | H41: Mô tả TS liên quan | I41: O | K41: N | Q41: Ẩn hiện tùy biến
F42: System | G42: Display | H42: Tên người sử dụng | I42: M | K42: N | Q42: Hiển thị mặc định
...

Sheet 5.4.0a
A1: <<<
B2: CẤP TÀI SẢN
B3: Phê duyệt yêu cầu cấp tài sản

Sheet 5.4.0b
A1: <<<
B2: CẤP TÀI SẢN
B3: Phê duyệt yêu cầu cấp tài sản
B5: 1 | C5: 2 | E5: 1 | F5: =E5+1 -> 2 | G5: =F5+1 -> 3 | H5: =G5+1 -> 4 | I5: =H5+1 -> 5 | J5: =I5+1 -> 6 | K5: =J5+1 -> 7 | L5: =K5+1 -> 8 | M5: =L5+1 -> 9 | ... U5: =T5+1 -> 17
B6: 1. Nhập thông tin tìm kiếm yêu cầu | C6: 1 | E6: Data | R6: Status | S6: Notification | T6: Template | U6: Biz rule
C7: 2 | E7: Tab/section | F7: Operator | G7: Action | H7: Field name VN | I7: M/O | J7: Field type | K7: Editable | L7: Max length | M7: Format | N7: Default value | O7: LOV | P7: Data source | Q7: Data rule
C8: AM | E8: Tasklist/Danh sách yêu cầu
F9: User | H9: Mã yêu cầu | I9: M | J9: Text | K9: N | L9: 20
F10: User | H10: Tiêu đề | I10: M | J10: Text | K10: N | L10: 150
F11: User | H11: Người tạo | I11: M | J11: List | K11: N | L11: 20
F12: User | H12: Trạng thái | I12: M | J12: List | K12: N | L12: 20
F13: User | H13: Ngày tạo | I13: M | J13: Date | K13: N | L13: 20
F14: User | H14: Loại cấp tài sản | I14: M | J14: List | K14: N | L14: 100
F15: User | H15: Người xử lý | I15: O | J15: List | K15: N | L15: 20
F16: User | H16: Ngày xác nhận | I16: O | J16: Date | K16: N | L16: 20
E17: Tìm kiếm yêu cầu
F18: User | G18: Input | H18: Mã yêu cầu | I18: M | J18: Text | K18: Y | L18: 20
F19: User | G19: Input | H19: Tiêu đề | I19: M | J19: Text | K19: Y | L19: 150
F20: User | G20: Select | H20: Người tạo | I20: M | J20: List | K20: Y | L20: 20
F21: User | G21: Select | H21: Trạng thái | I21: M | J21: List | K21: Y | L21: 20
F22: User | G22: Input | H22: Ngày tạo | I22: M | J22: Date | K22: Y | L22: 20
F23: User | G23: Select | H23: Loại cấp tài sản | I23: M | J23: List | K23: Y | L23: 100
F24: User | G24: Select | H24: Người xử lý | I24: M | J24: List | K24: Y | L24: 20
F25: User | G25: Input | H25: Ngày xác nhận | I25: M | J25: Date | K25: Y | L25: 20
B26: 2. Hiển thị kết quả tìm kiếm | C26: Hệ thống | E26: Danh sách yêu cầu
F27: System | H27: Mã yêu cầu | I27: M | J27: Text | K27: N | L27: 20
F28: System | H28: Tiêu đề | I28: M | J28: Text | K28: N | L28: 150
F29: System | H29: Người tạo | I29: M | J29: List | K29: N | L29: 20
F30: System | H30: Trạng thái | I30: M | J30: List | K30: N | L30: 20
F31: System | H31: Ngày tạo | I31: M | J31: Date | K31: N | L31: 20
F32: System | H32: Loại cấp tài sản | I32: M | J32: List | K32: N | L32: 100
F33: System | H33: Người xử lý | I33: O | J33: List | K33: N | L33: 20
F34: System | H34: Ngày xác nhận | I34: O | J34: Date | K34: N | L34: 20
B35: 3. Chọn yêu cầu, xem | C35: AM | F35: User | G35: Select | H35: Yêu cầu
E36: Thông tin chung
F37: System | G37: Display | H37: Số yêu cầu | I37: M | J37: Text | K37: N
F38: System | G38: Display | H38: Ngày tạo | I38: M | J38: Date | K38: N
F39: User | G39: Input | H39: Tiêu đề | I39: O | J39: Text | K39: N
E40: DS tài sản cấp
F41: System | G41: Display | H41: Mã tài sản | I41: M | K41: N | Q41: Hiển thị mặc định
...

Sheet 5.4.1a 
A1: <<<
B2: CẤP TÀI SẢN
B3: Tạo yêu cầu xuất kho

Sheet 5.4.1b 
A1: <<<
B2: ='5.4.1a '!B2 -> CẤP TÀI SẢN
B3: ='5.4.1a '!B3 -> Tạo yêu cầu xuất kho
B5: 1 | C5: 2 | E5: 1 | F5: =E5+1 -> 2 | G5: =F5+1 -> 3 | H5: =G5+1 -> 4 | I5: =H5+1 -> 5 | J5: =I5+1 -> 6 | K5: =J5+1 -> 7 | L5: =K5+1 -> 8 | M5: =L5+1 -> 9 | ... U5: =T5+1 -> 17
B6: 1. Tạo yêu cầu xuất kho | C6: 1 | E6: Data | R6: Status | S6: Notification | T6: Template | U6: Biz rule
C7: 2 | E7: Tab/section | F7: Operator | G7: Action | H7: Field name VN | I7: M/O | J7: Field type | K7: Editable | L7: Max length | M7: Format | N7: Default value | O7: LOV | P7: Data source | Q7: Data rule
C8: Hệ thống | E8: Hệ thống tự động tạo yêu cầu xuất kho theo thông tin trên phiếu cấp.
E9: Thông tin chung
F10: System | G10: Display | H10: Số yêu cầu | I10: M | J10: Text | K10: N | L10: 50 | M10: XK.YY.xxxx | Q10: YY = Year, xxxx = số chạy từ 1-9999 không dùng lại
F11: System | G11: Display | H11: Ngày tạo | I11: M | J11: Date | K11: N | L11: 50 | M11: MM.DD.YYYY | N11: Today
F12: System | G12: Input | H12: Tiêu đề | I12: O | J12: Text | K12: Y | L12: 150 | Q12: =Tiêu đề RQ Cấp/Thanh lý
E13: DS tài sản xuất kho | Q13: = Danh mục tài sản trong phiếu cấp/thanh lý
F14: System | G14: Display | H14: Mã tài sản | I14: M | K14: N | Q14: Hiển thị mặc định
F15: System | G15: Display | H15: Tên Tài sản | I15: M | K15: N | Q15: Hiển thị mặc định
F16: System | G16: Display | H16: Mô tả TS | I16: M | K16: N | Q16: Hiển thị mặc định
F17: System | G17: Display | H17: Trạng thái TS | I17: M | K17: N | Q17: Hiển thị mặc định
F18: System | G18: Display | H18: Phân nhóm TS (group name) | I18: M | K18: N | Q18: Hiển thị mặc định
F19: System | G19: Display | H19: Nhóm TS (CAT1) | I19: M | K19: N | Q19: Hiển thị mặc định
F20: System | G20: Display | H20: Số PO | I20: M | K20: N | Q20: Hiển thị mặc định
F21: System | G21: Display | H21: Tên nhà cung cấp | I21: O | K21: N | Q21: Ẩn hiện tùy biến
F22: System | G22: Display | H22: Nguyên giá TS (VAT incl) | I22: M | K22: N | Q22: Ẩn hiện tùy biến
F23: System | G23: Display | H23: Mã TS liên quan | I23: O | K23: N | Q23: Ẩn hiện tùy biến
F24: System | G24: Display | H24: Mô tả TS liên quan | I24: O | K24: N | Q24: Ẩn hiện tùy biến
F25: System | G25: Display | H25: Tên người sử dụng | I25: M | K25: N | Q25: Hiển thị mặc định
... F39: System | G39: Display | H39: Ngày bắt đầu sử dụng | I39: O | K39: N | Q39: Ẩn hiện tùy biến
E40: Thông tin kho xuất
F41: System/User | G41: Display/Search/Select | H41: Tên kho | I41: M | J41: List | K41: N | L41: 50 | Q41: = Thông tin kho trên RQ cấp/Thanh lý
F42: System | G42: Display | H42: Địa chỉ kho | I42: M | J42: Text | K42: Y | L42: 50 | P42: OMS
F43: System | G43: Display | H43: Quản lý kho | I43: M | J43: Text | K43: N | L43: 50 | P43: OMS
E44: Thông tin đầu mối nhận hàng
F45: User | G45: Input | H45: Đầu mối | I45: M | J45: Text | K45: Y | L45: 50
F46: User | G46: Input | H46: Số điện thoại | I46: M | J46: Number | K46: Y | L46: 52
F47: User | G47: Input | H47: Thời gian bàn giao | I47: O | J47: Date | K47: Y | L47: 50
E48: Ghi chú | F48: User | G48: Input | H48: Ghi chú | I48: M | J48: Text | K48: Y | L48: 150 | Q48: = Mã RQ cấp/thanh lý
E49: Hồ sơ đính kèm
F50: User | G50: Select | H50: Thêm | I50: M | J50: Button | K50: N
F51: User | G51: Select | H51: File | I51: M | K51: N
F52: System/User | G52: Display/Select | H52: Tên thư mục | I52: M | K52: N
F53: System/User | G53: Display/Input | H53: Tên tài liệu | I53: M | J53: Text | K53: N | L53: 150
F54: System | G54: Display | H54: Ngày | I54: M | K54: N
...

Sheet 5.4.2a 
A1: <<<
B2: XUẤT KHO TỪ CẤP TÀI SẢN
B3: Tiếp nhận yêu cầu xuất kho

Sheet 5.4.2b 
A1: <<<
B2: ='5.4.2a '!$B$2 -> XUẤT KHO TỪ CẤP TÀI SẢN
B3: ='5.4.2a '!$B$3 -> Tiếp nhận yêu cầu xuất kho
B5: 1 | C5: 2 | E5: 1 | F5: =E5+1 -> 2 | G5: =F5+1 -> 3 | H5: =G5+1 -> 4 | I5: =H5+1 -> 5 | J5: =I5+1 -> 6 | K5: =J5+1 -> 7 | L5: =K5+1 -> 8 | M5: =L5+1 -> 9 | ... U5: =T5+1 -> 17
B6: 1. Nhập thông tin tìm kiếm yêu cầu | C6: 1 | E6: Data | R6: Status | S6: Notification | T6: Template | U6: Biz rule
C7: 2 | E7: Tab/section | F7: Operator | G7: Action | H7: Field name VN | I7: M/O | J7: Field type | K7: Editable | L7: Max length | M7: Format | N7: Default value | O7: LOV | P7: Data source | Q7: Data rule
C8: WK | E8: Tasklist/Danh sách yêu cầu
F9: User | H9: Mã yêu cầu | I9: M | J9: Text | K9: N | L9: 20
F10: User | H10: Tiêu đề | I10: M | J10: Text | K10: N | L10: 150
F11: User | H11: Người tạo | I11: M | J11: List | K11: N | L11: 20
F12: User | H12: Trạng thái | I12: M | J12: List | K12: N | L12: 20
F13: User | H13: Ngày tạo | I13: M | J13: Date | K13: N | L13: 20
F14: User | H14: Nghiệp vụ kho | I14: M | J14: List | K14: N | L14: 100
F15: User | H15: Người xử lý | I15: O | J15: List | K15: N | L15: 20
F16: User | H16: Ngày xác nhận | I16: O | J16: Date | K16: N | L16: 20
E17: Tìm kiếm yêu cầu
F18: User | G18: Input | H18: Mã yêu cầu | I18: M | J18: Text | K18: Y | L18: 20
F19: User | G19: Input | H19: Tiêu đề | I19: M | J19: Text | K19: Y | L19: 150
F20: User | G20: Select | H20: Người tạo | I20: M | J20: List | K20: Y | L20: 20
F21: User | G21: Select | H21: Trạng thái | I21: M | J21: List | K21: Y | L21: 20
F22: User | G22: Input | H22: Ngày tạo | I22: M | J22: Date | K22: Y | L22: 20
F23: User | G23: Select | H23: Nghiệp vụ kho | I23: M | J23: List | K23: Y | L23: 100
F24: User | G24: Select | H24: Người xử lý | I24: M | J24: List | K24: Y | L24: 20
F25: User | G25: Input | H25: Ngày xác nhận | I25: M | J25: Date | K25: Y | L25: 20
B26: 2. Hiển thị kết quả tìm kiếm | C26: Hệ thống | E26: Danh sách yêu cầu
F27: System | H27: Mã yêu cầu | I27: M | J27: Text | K27: N | L27: 20
F28: System | H28: Tiêu đề | I28: M | J28: Text | K28: N | L28: 150
F29: System | H29: Người tạo | I29: M | J29: List | K29: N | L29: 20
F30: System | H30: Trạng thái | I30: M | J30: List | K30: N | L30: 20
F31: System | H31: Ngày tạo | I31: M | J31: Date | K31: N | L31: 20
F32: System | H32: Nghiệp vụ kho | I32: M | J32: List | K32: N | L32: 100
F33: System | H33: Người xử lý | I33: O | J33: List | K33: N | L33: 20
F34: System | H34: Ngày xác nhận | I34: O | J34: Date | K34: N | L34: 20
B35: 3. Chọn yêu cầu, xem | C35: WK | F35: User | G35: Select | H35: Yêu cầu
E36: Thông tin chung
F37: System | G37: Display | H37: Số yêu cầu | I37: M | J37: Text | K37: N | L37: 50 | M37: XK.YY.xxxx | Q37: YY = Year, xxxx = số chạy từ 1-9999 không dùng lại
F38: System | G38: Display | H38: Ngày tạo | I38: M | J38: Date | K38: N | L38: 50 | M38: MM.DD.YYYY | N38: Today
F39: System | G39: Input | H39: Tiêu đề | I39: O | J39: Text | K39: Y | L39: 150
E40: DS tài sản xuất kho | Q40: = Danh mục tài sản trong phiếu cấp/thanh lý
F41: System | G41: Display | H41: Mã tài sản | I41: M | K41: N | Q41: Hiển thị mặc định
...

Sheet 5.4.3a 
A1: <<<
B2: XUẤT KHO TỪ CẤP TÀI SẢN
B3: Phê duyệt yêu cầu xuất kho

Sheet 5.4.3b
A1: <<<
B2: ='5.4.3a '!B2 -> XUẤT KHO TỪ CẤP TÀI SẢN
B3: ='5.4.3a '!B3 -> Phê duyệt yêu cầu xuất kho
B5: 1 | C5: 2 | E5: 1 | F5: =E5+1 -> 2 | G5: =F5+1 -> 3 | H5: =G5+1 -> 4 | I5: =H5+1 -> 5 | J5: =I5+1 -> 6 | K5: =J5+1 -> 7 | L5: =K5+1 -> 8 | M5: =L5+1 -> 9 | ... U5: =T5+1 -> 17
B6: 1. Nhập thông tin tìm kiếm yêu cầu | C6: 1 | E6: Data | R6: Status | S6: Notification | T6: Template | U6: Biz rule
C7: 2 | E7: Tab/section | F7: Operator | G7: Action | H7: Field name VN | I7: M/O | J7: Field type | K7: Editable | L7: Max length | M7: Format | N7: Default value | O7: LOV | P7: Data source | Q7: Data rule
C8: Warehouse Mgr. | E8: Tasklist/Danh sách yêu cầu
F9: User | H9: Mã yêu cầu | I9: M | J9: Text | K9: N | L9: 20
F10: User | H10: Tiêu đề | I10: M | J10: Text | K10: N | L10: 150
F11: User | H11: Người tạo | I11: M | J11: List | K11: N | L11: 20
F12: User | H12: Trạng thái | I12: M | J12: List | K12: N | L12: 20
F13: User | H13: Ngày tạo | I13: M | J13: Date | K13: N | L13: 20
F14: User | H14: Nghiệp vụ kho | I14: M | J14: List | K14: N | L14: 100
F15: User | H15: Người xử lý | I15: O | J15: List | K15: N | L15: 20
F16: User | H16: Ngày xác nhận | I16: O | J16: Date | K16: N | L16: 20
E17: Tìm kiếm yêu cầu
F18: User | G18: Input | H18: Mã yêu cầu | I18: M | J18: Text | K18: Y | L18: 20
F19: User | G19: Input | H19: Tiêu đề | I19: M | J19: Text | K19: Y | L19: 150
F20: User | G20: Select | H20: Người tạo | I20: M | J20: List | K20: Y | L20: 20
F21: User | G21: Select | H21: Trạng thái | I21: M | J21: List | K21: Y | L21: 20
F22: User | G22: Input | H22: Ngày tạo | I22: M | J22: Date | K22: Y | L22: 20
F23: User | G23: Select | H23: Loại cấp tài sản | I23: M | J23: List | K23: Y | L23: 100
F24: User | G24: Select | H24: Người xử lý | I24: M | J24: List | K24: Y | L24: 20
F25: User | G25: Input | H25: Ngày xác nhận | I25: M | J25: Date | K25: Y | L25: 20
B26: 2. Hiển thị kết quả tìm kiếm | C26: Hệ thống | E26: Danh sách yêu cầu
F27: System | H27: Mã yêu cầu | I27: M | J27: Text | K27: N | L27: 20
F28: System | H28: Tiêu đề | I28: M | J28: Text | K28: N | L28: 150
F29: System | H29: Người tạo | I29: M | J29: List | K29: N | L29: 20
F30: System | H30: Trạng thái | I30: M | J30: List | K30: N | L30: 20
F31: System | H31: Ngày tạo | I31: M | J31: Date | K31: N | L31: 20
F32: System | H32: Nghiệp vụ kho | I32: M | J32: List | K32: N | L32: 100
F33: System | H33: Người xử lý | I33: O | J33: List | K33: N | L33: 20
F34: System | H34: Ngày xác nhận | I34: O | J34: Date | K34: N | L34: 20
B35: 3. Chọn yêu cầu, xem | C35: Warehouse Mgr. | F35: User | G35: Select | H35: Yêu cầu
E36: Thông tin chung
F37: System | G37: Display | H37: Số yêu cầu | I37: M | J37: Text | K37: N | L37: 50 | M37: XK.YY.xxxx | Q37: YY = Year, xxxx = số chạy từ 1-9999 không dùng lại
F38: System | G38: Display | H38: Ngày tạo | I38: M | J38: Date | K38: N | L38: 50 | M38: MM.DD.YYYY | N38: Today
F39: System | G39: Input | H39: Tiêu đề | I39: O | J39: Text | K39: Y | L39: 150
E40: DS tài sản xuất kho | Q40: = Danh mục tài sản trong phiếu cấp/thanh lý
F41: System | G41: Display | H41: Mã tài sản | I41: M | K41: N | Q41: Hiển thị mặc định
...

Sheet 5.4.4a
A1: <<<
B2: XUẤT KHO TỪ CẤP TÀI SẢN
B3: Nhận tài sản

Sheet 5.4.4b
A1: <<<
B2: ='5.4.3a '!B2 -> XUẤT KHO TỪ CẤP TÀI SẢN
B3: ='5.4.4a'!B3 -> Nhận tài sản
B5: 1 | C5: 2 | E5: 1 | F5: =E5+1 -> 2 | G5: =F5+1 -> 3 | H5: =G5+1 -> 4 | I5: =H5+1 -> 5 | J5: =I5+1 -> 6 | K5: =J5+1 -> 7 | L5: =K5+1 -> 8 | M5: =L5+1 -> 9 | ... U5: =T5+1 -> 17
B6: 1. Nhập thông tin tìm kiếm yêu cầu | C6: 1 | E6: Data | R6: Status | S6: Notification | T6: Template | U6: Biz rule
C7: 2 | E7: Tab/section | F7: Operator | G7: Action | H7: Field name VN | I7: M/O | J7: Field type | K7: Editable | L7: Max length | M7: Format | N7: Default value | O7: LOV | P7: Data source | Q7: Data rule
C8: BU user | E8: Tasklist/Danh sách yêu cầu
F9: User | H9: Mã yêu cầu | I9: M | J9: Text | K9: N | L9: 20
F10: User | H10: Tiêu đề | I10: M | J10: Text | K10: N | L10: 150
F11: User | H11: Người tạo | I11: M | J11: List | K11: N | L11: 20
F12: User | H12: Trạng thái | I12: M | J12: List | K12: N | L12: 20
F13: User | H13: Ngày tạo | I13: M | J13: Date | K13: N | L13: 20
F14: User | H14: Nghiệp vụ kho | I14: M | J14: List | K14: N | L14: 100
F15: User | H15: Người xử lý | I15: O | J15: List | K15: N | L15: 20
F16: User | H16: Ngày xác nhận | I16: O | J16: Date | K16: N | L16: 20
E17: Tìm kiếm yêu cầu
F18: User | G18: Input | H18: Mã yêu cầu | I18: M | J18: Text | K18: Y | L18: 20
F19: User | G19: Input | H19: Tiêu đề | I19: M | J19: Text | K19: Y | L19: 150
F20: User | G20: Select | H20: Người tạo | I20: M | J20: List | K20: Y | L20: 20
F21: User | G21: Select | H21: Trạng thái | I21: M | J21: List | K21: Y | L21: 20
F22: User | G22: Input | H22: Ngày tạo | I22: M | J22: Date | K22: Y | L22: 20
F23: User | G23: Select | H23: Nghiệp vụ kho | I23: M | J23: List | K23: Y | L23: 100
F24: User | G24: Select | H24: Người xử lý | I24: M | J24: List | K24: Y | L24: 20
F25: User | G25: Input | H25: Ngày xác nhận | I25: M | J25: Date | K25: Y | L25: 20
B26: 2. Hiển thị kết quả tìm kiếm | C26: Hệ thống | E26: Danh sách yêu cầu
F27: System | H27: Mã yêu cầu | I27: M | J27: Text | K27: N | L27: 20
F28: System | H28: Tiêu đề | I28: M | J28: Text | K28: N | L28: 150
F29: System | H29: Người tạo | I29: M | J29: List | K29: N | L29: 20
F30: System | H30: Trạng thái | I30: M | J30: List | K30: N | L30: 20
F31: System | H31: Ngày tạo | I31: M | J31: Date | K31: N | L31: 20
F32: System | H32: Nghiệp vụ kho | I32: M | J32: List | K32: N | L32: 100
F33: System | H33: Người xử lý | I33: O | J33: List | K33: N | L33: 20
F34: System | H34: Ngày xác nhận | I34: O | J34: Date | K34: N | L34: 20
B35: 3. Chọn yêu cầu, xem | C35: BU user | F35: User | G35: Select | H35: Yêu cầu
E36: Thông tin chung
F37: System | G37: Display | H37: Số yêu cầu | I37: M | J37: Text | K37: N | L37: 50 | M37: XK.YY.xxxx | Q37: YY = Year, xxxx = số chạy từ 1-9999 không dùng lại
F38: System | G38: Display | H38: Ngày tạo | I38: M | J38: Date | K38: N | L38: 50 | M38: MM.DD.YYYY | N38: Today
F39: System | G39: Input | H39: Tiêu đề | I39: O | J39: Text | K39: Y | L39: 150
E40: DS tài sản xuất kho | Q40: = Danh mục tài sản trong phiếu cấp/thanh lý
F41: System | G41: Display | H41: Mã tài sản | I41: M | K41: N | Q41: Hiển thị mặc định
...

Sheet 5.5.1a
A1: <<<
B2: HỦY YÊU CẦU XUẤT KHO

Sheet 5.5.1b
A1: <<<
B2: HỦY YÊU CẦU XUẤT KHO
B3: Điều kiện: | C3: Yêu cầu xuất kho đã tạo thành công và có trạng thái <> "Đã xác nhận"
B5: 1 | C5: 2 | E5: 1 | F5: =E5+1 -> 2 | G5: =F5+1 -> 3 | H5: =G5+1 -> 4 | I5: =H5+1 -> 5 | J5: =I5+1 -> 6 | K5: =J5+1 -> 7 | L5: =K5+1 -> 8 | M5: =L5+1 -> 9 | ... U5: =T5+1 -> 17
B6: 1. Nhập thông tin tìm kiếm yêu cầu | C6: 1 | E6: Data | R6: Status | S6: Notification | T6: Template | U6: Biz rule
C7: 2 | E7: Tab/section | F7: Operator | G7: Action | H7: Field name VN | I7: M/O | J7: Field type | K7: Editable | L7: Max length | M7: Format | N7: Default value | O7: LOV | P7: Data source | Q7: Data rule
C8: AMP | E8: Tasklist/Danh sách yêu cầu
F9: User | H9: Mã yêu cầu | I9: M | J9: Text | K9: N | L9: 20
F10: User | H10: Tiêu đề | I10: M | J10: Text | K10: N | L10: 150
F11: User | H11: Người tạo | I11: M | J11: List | K11: N | L11: 20
F12: User | H12: Trạng thái | I12: M | J12: List | K12: N | L12: 20
F13: User | H13: Ngày tạo | I13: M | J13: Date | K13: N | L13: 20
F14: User | H14: Nghiệp vụ kho | I14: M | J14: List | K14: N | L14: 100
F15: User | H15: Người xử lý | I15: O | J15: List | K15: N | L15: 20
F16: User | H16: Ngày xác nhận | I16: O | J16: Date | K16: N | L16: 20
E17: Tìm kiếm yêu cầu
F18: User | G18: Input | H18: Mã yêu cầu | I18: M | J18: Text | K18: Y | L18: 20
F19: User | G19: Input | H19: Tiêu đề | I19: M | J19: Text | K19: Y | L19: 150
F20: User | G20: Select | H20: Người tạo | I20: M | J20: List | K20: Y | L20: 20
F21: User | G21: Select | H21: Trạng thái | I21: M | J21: List | K21: Y | L21: 20
F22: User | G22: Input | H22: Ngày tạo | I22: M | J22: Date | K22: Y | L22: 20
F23: User | G23: Select | H23: Nghiệp vụ kho | I23: M | J23: List | K23: Y | L23: 100
F24: User | G24: Select | H24: Người xử lý | I24: M | J24: List | K24: Y | L24: 20
F25: User | G25: Input | H25: Ngày xác nhận | I25: M | J25: Date | K25: Y | L25: 20
B26: 2. Hiển thị kết quả tìm kiếm | C26: Hệ thống | E26: Danh sách yêu cầu
F27: System | H27: Mã yêu cầu | I27: M | J27: Text | K27: N | L27: 20
F28: System | H28: Tiêu đề | I28: M | J28: Text | K28: N | L28: 150
F29: System | H29: Người tạo | I29: M | J29: List | K29: N | L29: 20
F30: System | H30: Trạng thái | I30: M | J30: List | K30: N | L30: 20
F31: System | H31: Ngày tạo | I31: M | J31: Date | K31: N | L31: 20
F32: System | H32: Nghiệp vụ kho | I32: M | J32: List | K32: N | L32: 100
F33: System | H33: Người xử lý | I33: O | J33: List | K33: N | L33: 20
F34: System | H34: Ngày xác nhận | I34: O | J34: Date | K34: N | L34: 20
B35: 3. Chọn yêu cầu, xem | C35: AMP | F35: User | G35: Select | H35: Yêu cầu
E36: Thông tin chung
F37: System | G37: Display | H37: Số yêu cầu | I37: M | J37: Text | K37: N | L37: 50 | M37: XK.YY.xxxx | Q37: YY = Year, xxxx = số chạy từ 1-9999 không dùng lại
F38: System | G38: Display | H38: Ngày tạo | I38: M | J38: Date | K38: N | L38: 50 | M38: MM.DD.YYYY | N38: Today
F39: System | G39: Input | H39: Tiêu đề | I39: O | J39: Text | K39: Y | L39: 150
E40: DS tài sản xuất kho | Q40: = Danh mục tài sản trong phiếu cấp/thanh lý
F41: System | G41: Display | H41: Mã tài sản | I41: M | K41: N | Q41: Hiển thị mặc định
...

Sheet 5.6.1a
A1: <<<
B2: ĐIỀU CHUYỂN TÀI SẢN GIỮA CÁC KHO
B3: Tạo yêu cầu điều chuyển kho

Sheet 5.6.1b
A1: <<<
B2: ĐIỀU CHUYỂN TÀI SẢN GIỮA CÁC KHO
B3: Tạo yêu cầu điều chuyển kho
B5: 1 | C5: 2 | E5: 1 | F5: 2 | G5: 3 | H5: 4 | I5: 5 | J5: 6 | K5: 7 | L5: 8 | M5: 9 | N5: 10 | O5: 11 | P5: 12 | Q5: 13 | R5: 14 | S5: 15 | T5: 16 | U5: 17
B6: 1. Tạo yêu cầu, đính kèm, xem lại yêu cầu | C6: 1 | E6: Data | R6: Status | S6: Notification | T6: Template | U6: Biz rule
C7: 2 | E7: Tab/section | F7: Operator | G7: Action | H7: Field name VN | I7: M/O | J7: Field type | K7: Editable | L7: Max length | M7: Format | N7: Default value | O7: LOV | P7: Data source | Q7: Data rule
C8: AMP | F8: User | G8: Select | H8: Tạo | I8: M | J8: Button | K8: N
E9: Thông tin chung
F10: System | G10: Display | H10: Số yêu cầu | I10: M | J10: Text | K10: N | L10: 50 | M10: CK.YY.xxxx | Q10: YY = Year, xxxx = số chạy từ 1-9999 không dùng lại
F11: System | G11: Display | H11: Ngày tạo | I11: M | J11: Date | K11: N | L11: 50 | M11: MM.DD.YYYY | N11: Today
F12: User | G12: Input | H12: Tiêu đề | I12: O | J12: Text | K12: Y | L12: 150
F13: User | G13: Select | H13: Thêm tài sản | I13: M | J13: Button | K13: N
E14: Tìm kiếm tài sản
F15: User | G15: Input | H15: Mã tài sản | I15: O | J15: Text | K15: N | L15: 20
F16: User | G16: Input | H16: Tên tài sản | I16: O | J16: Text | K16: Y | L16: 20
F17: User | G17: Select | H17: Phân loại tài sản | I17: O | J17: List | K17: N | L17: 20
F18: User | G18: Select | H18: Nhóm tài sản | I18: O | J18: List | K18: N | L18: 20
F19: User | G19: Input | H19: PO number | I19: O | J19: Text | K19: Y | L19: 20
F20: User | G20: Select | H20: Trạng thái TS | I20: O | J20: List | K20: N | L20: 50
F21: User | G21: Select | H21: Tên nhà cung cấp | I21: O | J21: List | K21: N | L21: 50
F22: User | G22: Input | H22: Tên kho | I22: O | J22: List | K22: Y | L22: 50
F23: User | G23: Select | H23: Vị trí đặt tài sản | I23: O | J23: Text | K23: N | L23: 100
E24: DS kết quả tìm kiếm
F25: System | G25: Display | H25: Mã tài sản | I25: M | K25: N | Q25: Hiển thị mặc định
F26: System | G26: Display | H26: Tên Tài sản | I26: M | K26: N | Q26: Hiển thị mặc định
F27: System | G27: Display | H27: Mô tả TS | I27: M | K27: N | Q27: Hiển thị mặc định
F28: System | G28: Display | H28: Trạng thái TS | I28: M | K28: N | Q28: Hiển thị mặc định
F29: System | G29: Display | H29: Phân nhóm TS (group name) | I29: M | K29: N | Q29: Hiển thị mặc định
F30: System | G30: Display | H30: Nhóm TS (CAT1) | I30: M | K30: N | Q30: Hiển thị mặc định
F31: System | G31: Display | H31: Số PO | I31: M | K31: N | Q31: Hiển thị mặc định
F32: System | G32: Display | H32: Tên nhà cung cấp | I32: O | K32: N | Q32: Ẩn hiện tùy biến
F33: System | G33: Display | H33: Nguyên giá TS (VAT incl) | I33: M | K33: N | Q33: Ẩn hiện tùy biến
F34: System | G34: Display | H34: Mã TS liên quan | I34: O | K34: N | Q34: Ẩn hiện tùy biến
F35: System | G35: Display | H35: Mô tả TS liên quan | I35: O | K35: N | Q35: Ẩn hiện tùy biến
F36: System | G36: Display | H36: Tên người sử dụng | I36: M | K36: N | Q36: Hiển thị mặc định
... F50: System | G50: Display | H50: Ngày bắt đầu sử dụng | I50: O | K50: N | Q50: Ẩn hiện tùy biến
E51: DS tài sản điều chuyển
F52: System | G52: Display | H52: Mã tài sản | I52: M | K52: N | Q52: Hiển thị mặc định
F53: System | G53: Display | H53: Tên Tài sản | I53: M | K53: N | Q53: Hiển thị mặc định
F54: System | G54: Display | H54: Mô tả TS | I54: M | K54: N | Q54: Hiển thị mặc định
...

Sheet 5.6.2a
A1: <<<
B2: ĐIỀU CHUYỂN TÀI SẢN GIỮA CÁC KHO
B3: Phê duyệt yêu cầu điều chuyển kho

Sheet 5.6.2b
A1: <<<
B2: ĐIỀU CHUYỂN TÀI SẢN GIỮA CÁC KHO
B3: Phê duyệt yêu cầu điều chuyển kho
